Workbook

Sheet Praxen
A1: Nr. | B1: Praxis | C1: Stadtteil | D1: Bezirk / Region | E1: Adresse | F1: PLZ | G1: Telefon | H1: Google-Bewertung | I1: Anz. Bewertungen | J1: Öffnungszeiten (Kurzform) | K1: Hinweis / Schwerpunkt
A2: 1 | B2: Christiane Petersen Massage-Praxis | C2: Chorweiler | D2: Chorweiler | E2: Nikolaus-Groß-Straße 3 | F2: 50767 | G2: +49 221 5902270 | H2: 4.5 | I2: 11 | J2: auf Anfrage | K2: Reine Massagepraxis; Räume nur mit Vorhang getrennt
A3: 2 | B3: Physiotherapie Angelika Heyl | C3: Chorweiler | D3: Chorweiler | E3: Konrad-Hausmann-Straße 2 | F3: 50767 | G3: +49 221 5349366 | H3: 4.8 | I3: 10 | J3: Mo–Do 8:00–18:00, Fr bis 12:00 | K3: Kinder und Menschen mit Behinderung
A4: 3 | B4: Physiotherapie Ritterbeck | C4: Pesch | D4: Chorweiler | E4: Im Gewerbegebiet Pesch 13a | F4: 50767 | G4: +49 221 95318065 | H4: 4.3 | I4: 26 | J4: Mo–Do 8:00–19:00, Fr bis 16:00 | K4: Spezialtherapien vorher telefonisch erfragen
A5: 4 | B5: Physiotherapie Praxis Köln Seeberg | C5: Seeberg | D5: Chorweiler | E5: Kuskestraße 12 | F5: 50769 | G5: +49 221 94534449 | H5: 4.6 | I5: 70 | J5: Mo–Sa 8:00/9:00–17:00 | K5: Samstags offen, Manuelle Therapie, Osteopathie, Lymphdrainage
A6: 5 | B6: Praxis Hanneli Keijsers | C6: Seeberg | D6: Chorweiler | E6: Londoner Platz 2 | F6: 50765 | G6: +49 221 708017 | H6: 5 | I6: 4 | J6: Mo–Do 8:00–19:00, Fr bis 14:00 | K6: Hausbesuche, Lymphdrainage
A7: 6 | B7: Physio- & Ergotherapie Sylvia Pirnay | C7: Volkhoven/Weiler | D7: Chorweiler | E7: Martinusstraße 53 | F7: 50765 | G7: +49 221 7099885 | H7: 4.9 | I7: 59 | J7: Mo–Fr 7:00–20:00 | K7: Kinderphysio, Handtherapie; viele Terminverschiebungen
A8: 7 | B8: Sabine Heuel Physiotherapie | C8: Volkhoven/Weiler | D8: Chorweiler | E8: Weilerstraße 8 | F8: 50765 | G8: +49 221 76087667 | H8: 4.8 | I8: 5 | J8: Mo–Fr 8:00–19:00 | K8: Babys und Kleinkinder
A9: 8 | B9: Physiotherapiepraxis Sylvia Pirnay Worringen | C9: Worringen | D9: Chorweiler | E9: Hackhauser Weg 61 | F9: 50769 | G9: +49 221 782571 | H9: 4.7 | I9: 30 | J9: Mo–Fr 7:00–20:00 | K9: Kinderphysio, gut telefonisch erreichbar
A10: 9 | B10: APELOS Das Zentrum | C10: Ehrenfeld | D10: Ehrenfeld | E10: Vogelsanger Straße 78-80 | F10: 50823 | G10: +49 221 9529390 | H10: 4.8 | I10: 81 | J10: Mo–Do 7:30–17:00, Fr bis 14:00 | K10: Physio + Osteo + Ergo, keine Klimaanlage
A11: 10 | B11: BODYWORX Physiotherapie | C11: Ehrenfeld | D11: Ehrenfeld | E11: Venloer Straße 249 | F11: 50823 | G11: +49 221 56080255 | H11: 4.8 | I11: 93 | J11: Mo–Do 8:00–19:00, Fr bis 14:00 | K11: Rücken und Bandscheibe
A12: 11 | B12: Elementa Physio- & Ergotherapie | C12: Ehrenfeld | D12: Ehrenfeld | E12: Vogelsanger Straße 197d | F12: 50825 | G12: +49 221 89996899 | H12: 4.9 | I12: 176 | J12: Mo–Do 7:00–20:00, Fr bis 18:00 | K12: Physio + Ergo, Kinderbegleitung möglich
A13: 12 | B13: Kreuzburg Physiotherapie | C13: Ehrenfeld | D13: Ehrenfeld | E13: Gravenreuthstraße 25 | F13: 50823 | G13: +49 221 69050222 | H13: 4.8 | I13: 66 | J13: Mo–Do 7:00–20:00, Fr bis 16:00 | K13: Kulante Absageregelung
... A60: 59 | B60: Physiotherapie Petry | C60: Braunsfeld | D60: Lindenthal | E60: Aachener Straße 456 | F60: 50933 | G60: +49 221 5341377 | H60: 4.9 | I60: 28 | J60: Mo–Do 8:00–20:00, Fr bis 16:00 | K60: Englischsprachig, Hüfte und Rücken
A61: 60 | B61: Romain Gragnoli Physiotherapie | C61: Braunsfeld | D61: Lindenthal | E61: Aachener Straße 524/528 | F61: 50933 | H61: 5 | I61: 21 | J61: Mo–Fr 8:00–18:00 | K61: Deutsch und Französisch, Knie-Reha
A62: 61 | B62: BKP – Berkay Kuralay Physiotherapie | C62: Junkersdorf | D62: Lindenthal | E62: Wilhelm-Schlombs-Allee 2 | F62: 50858 | G62: +49 176 32137853 | H62: 5 | I62: 33 | J62: Mo–Fr 8:00–20:00 | K62: Moderne Geräte, Knie nach Skiunfall
A63: 62 | B63: Physio Wela | C63: Junkersdorf | D63: Lindenthal | E63: Kölner Weg 7 | F63: 50858 | G63: +49 163 2522294 | H63: 5 | I63: 15 | J63: Mo–Do 10:00–19:00, Di/Fr früher | K63: Neu eröffnet, Physio und Wellness
A64: 63 | B64: Praxis für Physiotherapie Elmar Hochhaus | C64: Junkersdorf | D64: Lindenthal | E64: Wiener Weg 14 | F64: 50858 | G64: +49 221 57003490 | H64: 5 | I64: 9 | J64: auf Anfrage | K64: Sportverletzungen; keine Nachmittagstermine
A65: 64 | B65: Enwavement SportsPhysiotherapy | C65: Lindenthal | D65: Lindenthal | E65: Luxemburger Straße 154 | F65: 50937 | G65: +49 1525 4558300 | H65: 5 | I65: 35 | J65: Mo–Do bis 20:00, Fr bis 16:30 | K65: Sportphysio, Kreuzband-Reha; kleine Räume
A66: 65 | B66: Krankengymnastik & Massage Susanne Gersabeck | C66: Lindenthal | D66: Lindenthal | E66: Luxemburger Straße 266 | F66: 50937 | G66: +49 221 28272044 | H66: 4.5 | I66: 2 | J66: auf Anfrage | K66: Kleine, familiäre Praxis
A67: 66 | B67: NOVOTERGUM Physiotherapie Lindenthal | C67: Lindenthal | D67: Lindenthal | E67: Gleueler Straße 277 | F67: 50935 | G67: +49 221 4300512 | H67: 4.7 | I67: 108 | J67: Mo–Do 8:00–20:00, Sa 9:00–14:00 | K67: Samstags offen, auch Hausbesuche
A68: 67 | B68: Physio Forte | C68: Lindenthal | D68: Lindenthal | E68: Lindenthalgürtel 46 | F68: 50935 | G68: +49 221 29871643 | H68: 4.9 | I68: 76 | J68: Mo–Do 9:00–19:00, Fr bis 17:00 | K68: Hydrojet-Massage; teils wechselnde Therapeuten
A69: 68 | B69: Physio ZWEIPUNKTNULL | C69: Lindenthal | D69: Lindenthal | E69: Geibelstraße 29 | F69: 50931 | G69: +49 221 71731666 | H69: 5 | I69: 100 | J69: Mo–Do 8:00–20:00, Fr geschlossen | K69: Neubau mit Trainingsfläche; freitags zu
A70: 69 | B70: Physio-Atelier Arman Dogru | C70: Lindenthal | D70: Lindenthal | E70: Gustavstraße 6 | F70: 50937 | G70: +49 1575 6297040 | H70: 5 | I70: 20 | J70: Mo–Fr 8:30–18:30 | K70: Manuelle Therapie, Faszien, Yoga; gesetzlich und privat
A71: 70 | B71: PhysioAktiv Köln | C71: Lindenthal | D71: Lindenthal | E71: Berrenrather Straße 339 | F71: 50937 | G71: +49 221 42327477 | H71: 4.4 | I71: 16 | J71: Mo–Do 8:00–19:00, Fr bis 14:30 | K71: Helle Räume; Kritik an Abrechnung/Datenschutz
A72: 71 | B72: Physiotherapie VCM Hypokrathion Lindenthal | C72: Lindenthal | D72: Lindenthal | E72: Dürener Straße 199-203 | F72: 50931 | G72: +49 179 7632694 | H72: 4.9 | I72: 57 | J72: Mo–Fr 7:00–19:00, Sa 9:00–13:00 | K72: Samstags offen, Sportverletzungen, Bandscheibe
A73: 72 | B73: Praxis Hennecke – Lindenthal 1 | C73: Lindenthal | D73: Lindenthal | E73: Lindenthalgürtel 102 | F73: 50935 | G73: +49 221 404554 | H73: 5 | I73: 20 | J73: Mo–Do 8:00–19:00, Fr bis 17:30 | K73: Beckenboden und Inkontinenztherapie
... A88: 87 | B88: Pro Physio Rinke Weiden | C88: Weiden | D88: Lindenthal | E88: Kronstädter Straße 100 | F88: 50858 | G88: +49 2234 9673319 | H88: 4.7 | I88: 58 | J88: Mo–Do 8:00–20:00, Fr bis 16:30 | K88: Lymphdrainage, Schulter- und Knorpel-Reha
A89: 88 | B89: Praxis für Physiotherapie Buchheim | C89: Buchheim | D89: Mülheim | E89: Alte Wipperfürther Straße 6 | F89: 51065 | H89: 5 | I89: 3 | J89: auf Anfrage | K89: Schulter und Arm, schnelle Termine
A90: 89 | B90: Physiotherapie Kaspers-Haupt | C90: Dünnwald | D90: Mülheim | E90: Im Weidenbruch 116A | F90: 51061 | G90: +49 221 632514 | H90: 4.6 | I90: 24 | J90: Mo–Do 7:30–20:00, Fr bis 14:00 | K90: Schwindel und Nackenverspannung
A91: 90 | B91: Physiotherapie Wolfram Kreutzfeldt | C91: Dünnwald | D91: Mülheim | E91: Honschaftsstraße 288A | F91: 51061 | G91: +49 221 635510 | H91: 4.8 | I91: 33 | J91: Mo–Fr 8:00–12:30, teils nachmittags | K91: Familiäre Praxis, Mittagspause beachten
A92: 91 | B92: IhrPhysio Alexej Teperschmidt | C92: Höhenhaus | D92: Mülheim | E92: Bergisch Gladbacher Straße 700 | F92: 51067 | G92: +49 221 6802080 | H92: 4.7 | I92: 12 | J92: Mo–Fr 8:00–18:00 | K92: Sehr flexible Terminvergabe, wechselnde Übungen
A93: 92 | B93: Praxis Julia Fleischer | C93: Höhenhaus | D93: Mülheim | E93: Florentine-Eichler-Straße 58 | F93: 51067 | G93: +49 221 67117993 | H93: 5 | I93: 5 | J93: auf Anfrage | K93: Einzeltherapeutin, breites Fachwissen
A94: 93 | B94: Praxis Udo Dahmen | C94: Höhenhaus | D94: Mülheim | E94: Rodstraße 2 | F94: 51067 | G94: +49 221 97774507 | H94: 4.8 | I94: 18 | J94: Mo–Do 8:00–17:00, Fr bis 15:00 | K94: Physio + Osteopathie, 2 Parkplätze
A95: 94 | B95: Privatpraxis für Physiotherapie GK | C95: Höhenhaus | D95: Mülheim | E95: Heinz-Kühn-Straße 39 | F95: 51067 | G95: +49 221 27225351 | H95: 5 | I95: 18 | J95: Mo–Fr 9:00–18:00 (Mi/Fr kürzer) | K95: Privatpraxis, lange Termine, Hausbesuche
A96: 95 | B96: Praxis Maria Andretzki | C96: Mülheim | D96: Mülheim | E96: Herler Straße 101 | F96: 51067 | G96: +49 221 96447340 | H96: 5 | I96: 29 | J96: Mo–Do 8:00–20:00, Fr bis 14:00 | K96: Schulter, gut organisiert
A97: 96 | B97: Praxis Thomas Krämer | C97: Mülheim | D97: Mülheim | E97: Bergisch Gladbacher Straße 408/412 | F97: 51067 | G97: +49 221 6087747 | H97: 4.4 | I97: 12 | J97: Mo–Do 7:30–20:00, Fr bis 15:30 | K97: Osteopathie, Migräne-Schwerpunkt
A98: 97 | B98: myPhysio Physiotherapie Köln Mülheim | C98: Mülheim | D98: Mülheim | E98: Buchheimer Straße 37 | F98: 51063 | G98: +49 221 47450990 | H98: 5 | I98: 32 | J98: Mo–Do bis 19:00/20:00, Fr bis 16:30 | K98: Knie-Reha, Lymphdrainage, flexible Termine
A99: 98 | B99: Die Therapeuten | C99: Longerich | D99: Nippes | E99: An den Kreutzmorgen 2 | F99: 50737 | G99: +49 221 7400777 | H99: 4.7 | I99: 29 | J99: Mo–Fr 7:00–18:30 | K99: Frühtermine ab 7 Uhr
A100: 99 | B100: Physioteam Longerich | C100: Longerich | D100: Nippes | E100: Rambouxstraße 132N | F100: 50737 | G100: +49 221 7406545 | H100: 4.6 | I100: 20 | J100: Mo–Do 8:00–18:30, Fr bis 14:00 | K100: Nimmt oft noch Neupatienten auf
...

Sheet Übersicht
A1: Übersicht: Anzahl Praxen je Bezirk / Region
A3: Bezirk / Region | B3: Anzahl Praxen | C3: Ø Bewertung
A4: Chorweiler | B4: =COUNTIF(Praxen!$D$2:$D$172,$A4) -> 8 | C4: =IFERROR(AVERAGEIFS(Praxen!$H$2:$H$172,Praxen!$D$2:$D$172,$A4,Praxen!$H$2:$H$172,">0"),"-") -> 4.7
A5: Ehrenfeld | B5: =COUNTIF(Praxen!$D$2:$D$172,$A5) -> 12 | C5: =IFERROR(AVERAGEIFS(Praxen!$H$2:$H$172,Praxen!$D$2:$D$172,$A5,Praxen!$H$2:$H$172,">0"),"-") -> 4.8416667
A6: Innenstadt | B6: =COUNTIF(Praxen!$D$2:$D$172,$A6) -> 21 | C6: =IFERROR(AVERAGEIFS(Praxen!$H$2:$H$172,Praxen!$D$2:$D$172,$A6,Praxen!$H$2:$H$172,">0"),"-") -> 4.8095238
A7: Kalk | B7: =COUNTIF(Praxen!$D$2:$D$172,$A7) -> 14 | C7: =IFERROR(AVERAGEIFS(Praxen!$H$2:$H$172,Praxen!$D$2:$D$172,$A7,Praxen!$H$2:$H$172,">0"),"-") -> 4.7142857
A8: Lindenthal | B8: =COUNTIF(Praxen!$D$2:$D$172,$A8) -> 32 | C8: =IFERROR(AVERAGEIFS(Praxen!$H$2:$H$172,Praxen!$D$2:$D$172,$A8,Praxen!$H$2:$H$172,">0"),"-") -> 4.884375
A9: Mülheim | B9: =COUNTIF(Praxen!$D$2:$D$172,$A9) -> 10 | C9: =IFERROR(AVERAGEIFS(Praxen!$H$2:$H$172,Praxen!$D$2:$D$172,$A9,Praxen!$H$2:$H$172,">0"),"-") -> 4.83
A10: Nippes | B10: =COUNTIF(Praxen!$D$2:$D$172,$A10) -> 17 | C10: =IFERROR(AVERAGEIFS(Praxen!$H$2:$H$172,Praxen!$D$2:$D$172,$A10,Praxen!$H$2:$H$172,">0"),"-") -> 4.6875
A11: Porz | B11: =COUNTIF(Praxen!$D$2:$D$172,$A11) -> 6 | C11: =IFERROR(AVERAGEIFS(Praxen!$H$2:$H$172,Praxen!$D$2:$D$172,$A11,Praxen!$H$2:$H$172,">0"),"-") -> 4.7166667
A12: Rodenkirchen | B12: =COUNTIF(Praxen!$D$2:$D$172,$A12) -> 22 | C12: =IFERROR(AVERAGEIFS(Praxen!$H$2:$H$172,Praxen!$D$2:$D$172,$A12,Praxen!$H$2:$H$172,">0"),"-") -> 4.805
A13: Umland | B13: =COUNTIF(Praxen!$D$2:$D$172,$A13) -> 29 | C13: =IFERROR(AVERAGEIFS(Praxen!$H$2:$H$172,Praxen!$D$2:$D$172,$A13,Praxen!$H$2:$H$172,">0"),"-") -> 4.8034483
A14: Gesamt | B14: =SUM(B4:B13) -> 171 | C14: =IFERROR(AVERAGEIF(Praxen!$H$2:$H$172,">0"),"-") -> 4.797619
A16: Quelle: Google-Places-Recherche, Stand 26.07.2026. Bewertungen und Öffnungszeiten sind Momentaufnahmen.
A17: Die Liste ist eine breite Auswahl, keine amtliche Vollerfassung. Für ein komplettes Verzeichnis:
A18: • physio-deutschland.de → Therapeutensuche (Verband, filterbar nach PLZ und Spezialisierung)
A19: • Therapeutensuche der eigenen Krankenkasse (zeigt, wer Kassenverordnungen abrechnet)
A20: Leere Bewertungsfelder = bei Google (noch) keine Bewertungen vorhanden.
